2022-03-28 12:52:45,805 ERROR: Exception on /user/test [GET] [in C:\Users\junting.ma\Documents\Documents\Anaconda\envs\flask\lib\site-packages\flask\app.py:1457]
Traceback (most recent call last):
  File "C:\Users\junting.ma\Documents\Documents\Anaconda\envs\flask\lib\site-packages\flask\app.py", line 2073, in wsgi_app
    response = self.full_dispatch_request()
  File "C:\Users\junting.ma\Documents\Documents\Anaconda\envs\flask\lib\site-packages\flask\app.py", line 1518, in full_dispatch_request
    rv = self.handle_user_exception(e)
  File "C:\Users\junting.ma\Documents\Documents\Anaconda\envs\flask\lib\site-packages\flask\app.py", line 1516, in full_dispatch_request
    rv = self.dispatch_request()
  File "C:\Users\junting.ma\Documents\Documents\Anaconda\envs\flask\lib\site-packages\flask\app.py", line 1502, in dispatch_request
    return self.ensure_sync(self.view_functions[rule.endpoint])(**req.view_args)
  File "C:\Users\junting.ma\Documents\Documents\Anaconda\envs\flask\lib\site-packages\flask_login\utils.py", line 272, in decorated_view
    return func(*args, **kwargs)
  File "C:\Users\junting.ma\Documents\Documents\GitHub\practice\flask\app\routes.py", line 121, in user
    posts = Post.query.filter_by(author.username == username).order_by(Post.timestamp.desc()).all()
NameError: name 'author' is not defined
2022-03-28 13:03:28,480 INFO: Hello [in C:\Users\junting.ma\Documents\Documents\GitHub\practice\flask\app\__init__.py:33]
2022-03-28 17:44:28,896 INFO: Hello [in C:\Users\junting.ma\Documents\Documents\GitHub\practice\flask\app\__init__.py:33]
